<?xml version="1.0" encoding="utf-8"?>
<!-- =================================================================================== -->
<!-- |    This document was autogenerated by xacro from /home/aidar/dev_ws/src/strirus_gait_planner/physical_object/robot_description/robot_description_simulation/xarco/strirus_gamma.xacro | -->
<!-- |    EDITING THIS FILE BY HAND IS NOT RECOMMENDED                                 | -->
<!-- =================================================================================== -->
<robot name="strirus_gamma">
  <gazebo>
    <self_collide>1</self_collide>
  </gazebo>
  <!--  <xacro:arg name="namespace" default="/"/>
        <xacro:property name="namespace" value="$(arg namespace)" /> -->
  <!-- Constants for simulating -->
  <!-- Xacro arg provides xacro.py file.xacro real_number_of_legs:=12 -->
  <!-- Import Rviz colors -->
  <material name="black">
    <color rgba="0.0 0.0 0.0 1.0"/>
  </material>
  <material name="blue">
    <color rgba="0.0 0.0 0.8 1.0"/>
  </material>
  <material name="green">
    <color rgba="0.0 0.8 0.0 1.0"/>
  </material>
  <material name="grey">
    <color rgba="0.2 0.2 0.2 1.0"/>
  </material>
  <material name="orange">
    <color rgba="1.0 0.423529411765 0.0392156862745 1.0"/>
  </material>
  <material name="brown">
    <color rgba="0.870588235294 0.811764705882 0.764705882353 1.0"/>
  </material>
  <material name="red">
    <color rgba="0.8 0.0 0.0 1.0"/>
  </material>
  <material name="white">
    <color rgba="1.0 1.0 1.0 1.0"/>
  </material>
  <!-- Body description -->
  <link name="base_footprint"/>
  <joint name="base_footprint_body_1_part_fixed" type="fixed">
    <parent link="base_footprint"/>
    <child link="body_1_part"/>
    <origin rpy="0  0  0" xyz="0 0 0.07"/>
  </joint>
  <link name="tof_camera_2"/>
  <joint name="body_2_part_tof_camera_2_fixed" type="fixed">
    <parent link="body_2_part"/>
    <child link="tof_camera_2"/>
    <origin rpy="0  0  0" xyz="0.2845 0 0"/>
  </joint>
  <link name="imu_2"/>
  <joint name="body_2_part_imu_2_fixed" type="fixed">
    <parent link="body_2_part"/>
    <child link="imu_2"/>
    <origin rpy="0  0  0" xyz="0.247 0 0"/>
  </joint>
  <!-- omni_deg in DEG!! not  in rad -->
  <!--body 1 part -->
  <link name="body_1_part">
    <inertial>
      <mass value="2.388930632"/>
      <origin rpy="0  0  0" xyz="0.093004592 -0.000003767 -0.002393165"/>
      <inertia ixx="0.028615853" ixy="-0.000001152" ixz="0.000120378" iyy="0.016244340" iyz="0.000000235" izz="0.043868564"/>
    </inertial>
    <collision>
      <origin rpy="0  0  0" xyz="0 0 0"/>
      <geometry>
        <mesh filename="../meshes/stl/collision/body_1_30_part.stl" scale="1 1 1"/>
      </geometry>
    </collision>
    <visual>
      <origin rpy="0  0  0" xyz="0 0 0"/>
      <geometry>
        <mesh filename="../meshes/stl/visual/body_1_30_part.stl" scale="1 1 1"/>
      </geometry>
      <material name="white"/>
    </visual>
  </link>
  <link name="tof_camera_1">
        </link>
  <joint name="body_1_part_tof_camera_1_fixed" type="fixed">
    <parent link="body_1_part"/>
    <child link="tof_camera_1"/>
    <origin rpy="0  0  3.14159265359" xyz="-0.0375 0 0"/>
  </joint>
  <link name="imu_1">
        </link>
  <joint name="body_1_part_imu_1_fixed" type="fixed">
    <parent link="body_1_part"/>
    <child link="imu_1"/>
    <origin rpy="0  0  0" xyz="0 0 0"/>
  </joint>
  <!--body 2 part -->
  <link name="body_2_part">
    <inertial>
      <mass value="2.355831379"/>
      <origin rpy="0  0  0" xyz="0.154054200 0.000005875 -0.002719841"/>
      <inertia ixx="0.028590553" ixy="-0.000001706" ixz="-0.000116523" iyy="0.016208890" iyz="-0.000000101" izz="0.043844764"/>
    </inertial>
    <collision>
      <origin rpy="0  0  0" xyz="0 0 0"/>
      <geometry>
        <mesh filename="../meshes/stl/collision/body_2_30_part.stl" scale="1 1 1"/>
      </geometry>
    </collision>
    <visual>
      <origin rpy="0  0  0" xyz="0 0 0"/>
      <geometry>
        <mesh filename="../meshes/stl/visual/body_2_30_part.stl" scale="1 1 1"/>
      </geometry>
      <material name="orange"/>
    </visual>
  </link>
  <!-- bridge part -->
  <!-- brdige 1 part -->
  <link name="bridge_1_part">
    <inertial>
      <mass value="0.093452612"/>
      <origin rpy="0  0  0" xyz="0.006688724 0.000000000 0.000077504"/>
      <inertia ixx="0.000234667" ixy="0.000000000" ixz="0.000000048" iyy="0.000029584" iyz="0.000000000" izz="0.000231388"/>
    </inertial>
    <collision>
      <origin rpy="0  0  0" xyz="0 0 0"/>
      <geometry>
        <mesh filename="../meshes/stl/collision/bridge_1_part.stl" scale="1 1 1"/>
      </geometry>
    </collision>
    <visual>
      <origin rpy="0  0  0" xyz="0 0 0"/>
      <geometry>
        <mesh filename="../meshes/stl/visual/bridge_1_part.stl" scale="1 1 1"/>
      </geometry>
      <material name="white"/>
    </visual>
  </link>
  <!-- brdige 2 part -->
  <link name="bridge_2_part">
    <inertial>
      <mass value="0.093452612"/>
      <origin rpy="0  0  0" xyz="0.023311276 0.000000000 0.000077504"/>
      <inertia ixx="0.000215112" ixy="0.000000000" ixz="0.000000048" iyy="0.000029584" iyz="0.000000000" izz="0.000211832"/>
    </inertial>
    <collision>
      <origin rpy="0  0  0" xyz="-0 0 0"/>
      <geometry>
        <mesh filename="../meshes/stl/collision/bridge_2_part.stl" scale="1 1 1"/>
      </geometry>
    </collision>
    <visual>
      <origin rpy="0  0  0" xyz="-0 0 0"/>
      <geometry>
        <mesh filename="../meshes/stl/visual/bridge_2_part.stl" scale="1 1 1"/>
      </geometry>
      <material name="orange"/>
    </visual>
  </link>
  <joint name="segment_up_revolute" type="revolute">
    <parent link="bridge_1_part"/>
    <child link="bridge_2_part"/>
    <origin rpy="0 -0.0 0" xyz="0.03 0 0"/>
    <axis xyz="0 -1  0"/>
    <limit effort="5" lower="-1.308996939" upper="1.308996939" velocity="0.5"/>
  </joint>
  <joint name="segment_side_revolute" type="revolute">
    <parent link="body_1_part"/>
    <child link="bridge_1_part"/>
    <origin rpy="0 0 -0.0" xyz="0.247 0 0"/>
    <axis xyz="0 0  -1"/>
    <limit effort="5" lower="-0.261799387799" upper="0.261799387799" velocity="0.5"/>
  </joint>
  <joint name="bridge_2_part_body_2_part_fixed" type="fixed">
    <parent link="bridge_2_part"/>
    <child link="body_2_part"/>
    <origin rpy="0 0 0" xyz="0.03 0 0"/>
  </joint>
  <!--===================== Link description =====================-->
  <link name="leg_left_5">
    <inertial>
      <mass value="0.012706347"/>
      <origin rpy="0 0 0" xyz="-0.013348671 0 -0.027584119"/>
      <inertia ixx="0.000007895" ixy="0" ixz="0.000001300" iyy="0.000009763" iyz="0" izz="0.000002004"/>
    </inertial>
    <collision>
      <origin rpy="0  0  0" xyz="0 0 0"/>
      <geometry>
        <mesh filename="../meshes/stl/collision/leg_70.stl" scale="1 1 1"/>
      </geometry>
    </collision>
    <visual>
      <origin rpy="0  0  0" xyz="0 0 0"/>
      <geometry>
        <mesh filename="../meshes/stl/visual/leg_70.stl" scale="1 1 1"/>
      </geometry>
      <material name="white"/>
    </visual>
  </link>
  <!--===================== Joint description =====================-->
  <joint name="leg_left_5_revolute_joint" type="revolute">
    <child link="leg_left_5"/>
    <parent link="body_2_part"/>
    <origin rpy="0       10.471975512        -0.523598775598" xyz="0.06325 0.1789304353  0"/>
    <!--=============== Joint properties ===============-->
    <axis xyz="0 -1  0"/>
    <!-- Check -->
    <limit effort="1.5" lower="-1e+5" upper="1e+5" velocity="3.0"/>
  </joint>
  <!--===================== Link description =====================-->
  <link name="leg_left_4">
    <inertial>
      <mass value="0.012706347"/>
      <origin rpy="0 0 0" xyz="-0.013348671 0 -0.027584119"/>
      <inertia ixx="0.000007895" ixy="0" ixz="0.000001300" iyy="0.000009763" iyz="0" izz="0.000002004"/>
    </inertial>
    <collision>
      <origin rpy="0  0  0" xyz="0 0 0"/>
      <geometry>
        <mesh filename="../meshes/stl/collision/leg_70.stl" scale="1 1 1"/>
      </geometry>
    </collision>
    <visual>
      <origin rpy="0  0  0" xyz="0 0 0"/>
      <geometry>
        <mesh filename="../meshes/stl/visual/leg_70.stl" scale="1 1 1"/>
      </geometry>
      <material name="white"/>
    </visual>
  </link>
  <!--===================== Joint description =====================-->
  <joint name="leg_left_4_revolute_joint" type="revolute">
    <child link="leg_left_4"/>
    <parent link="body_2_part"/>
    <origin rpy="0       8.37758040957        -0.523598775598" xyz="0.16925 0.1789304353  0"/>
    <!--=============== Joint properties ===============-->
    <axis xyz="0 -1  0"/>
    <!-- Check -->
    <limit effort="1.5" lower="-1e+5" upper="1e+5" velocity="3.0"/>
  </joint>
  <!--===================== Link description =====================-->
  <link name="leg_left_3">
    <inertial>
      <mass value="0.012706347"/>
      <origin rpy="0 0 0" xyz="-0.013348671 0 -0.027584119"/>
      <inertia ixx="0.000007895" ixy="0" ixz="0.000001300" iyy="0.000009763" iyz="0" izz="0.000002004"/>
    </inertial>
    <collision>
      <origin rpy="0  0  0" xyz="0 0 0"/>
      <geometry>
        <mesh filename="../meshes/stl/collision/leg_70.stl" scale="1 1 1"/>
      </geometry>
    </collision>
    <visual>
      <origin rpy="0  0  0" xyz="0 0 0"/>
      <geometry>
        <mesh filename="../meshes/stl/visual/leg_70.stl" scale="1 1 1"/>
      </geometry>
    </visual>
  </link>
  <!--===================== Joint description =====================-->
  <joint name="leg_left_3_revolute_joint" type="revolute">
    <child link="leg_left_3"/>
    <parent link="body_2_part"/>
    <origin rpy="0       6.28318530718        -0.523598775598" xyz="0.27525 0.1789304353  0"/>
    <!--=============== Joint properties ===============-->
    <axis xyz="0 -1  0"/>
    <!-- Check -->
    <limit effort="1.5" lower="-1e+5" upper="1e+5" velocity="3.0"/>
  </joint>
  <!--===================== Link description =====================-->
  <link name="leg_left_2">
    <inertial>
      <mass value="0.012706347"/>
      <origin rpy="0 0 0" xyz="-0.013348671 0 -0.027584119"/>
      <inertia ixx="0.000007895" ixy="0" ixz="0.000001300" iyy="0.000009763" iyz="0" izz="0.000002004"/>
    </inertial>
    <collision>
      <origin rpy="0  0  0" xyz="0 0 0"/>
      <geometry>
        <mesh filename="../meshes/stl/collision/leg_70.stl" scale="1 1 1"/>
      </geometry>
    </collision>
    <visual>
      <origin rpy="0  0  0" xyz="0 0 0"/>
      <geometry>
        <mesh filename="../meshes/stl/visual/leg_70.stl" scale="1 1 1"/>
      </geometry>
    </visual>
  </link>
  <!--===================== Joint description =====================-->
  <joint name="leg_left_2_revolute_joint" type="revolute">
    <child link="leg_left_2"/>
    <parent link="body_1_part"/>
    <origin rpy="0       4.18879020479        0.523598775598" xyz="0.18375 0.1789304353  0"/>
    <!--=============== Joint properties ===============-->
    <axis xyz="0 -1  0"/>
    <!-- Check -->
    <limit effort="1.5" lower="-1e+5" upper="1e+5" velocity="3.0"/>
  </joint>
  <!--===================== Link description =====================-->
  <link name="leg_left_1">
    <inertial>
      <mass value="0.012706347"/>
      <origin rpy="0 0 0" xyz="-0.013348671 0 -0.027584119"/>
      <inertia ixx="0.000007895" ixy="0" ixz="0.000001300" iyy="0.000009763" iyz="0" izz="0.000002004"/>
    </inertial>
    <collision>
      <origin rpy="0  0  0" xyz="0 0 0"/>
      <geometry>
        <mesh filename="../meshes/stl/collision/leg_70.stl" scale="1 1 1"/>
      </geometry>
    </collision>
    <visual>
      <origin rpy="0  0  0" xyz="0 0 0"/>
      <geometry>
        <mesh filename="../meshes/stl/visual/leg_70.stl" scale="1 1 1"/>
      </geometry>
    </visual>
  </link>
  <!--===================== Joint description =====================-->
  <joint name="leg_left_1_revolute_joint" type="revolute">
    <child link="leg_left_1"/>
    <parent link="body_1_part"/>
    <origin rpy="0       2.09439510239        0.523598775598" xyz="0.07775 0.1789304353  0"/>
    <!--=============== Joint properties ===============-->
    <axis xyz="0 -1  0"/>
    <!-- Check -->
    <limit effort="1.5" lower="-1e+5" upper="1e+5" velocity="3.0"/>
  </joint>
  <!--===================== Link description =====================-->
  <link name="leg_left_0">
    <inertial>
      <mass value="0.012706347"/>
      <origin rpy="0 0 0" xyz="-0.013348671 0 -0.027584119"/>
      <inertia ixx="0.000007895" ixy="0" ixz="0.000001300" iyy="0.000009763" iyz="0" izz="0.000002004"/>
    </inertial>
    <collision>
      <origin rpy="0  0  0" xyz="0 0 0"/>
      <geometry>
        <mesh filename="../meshes/stl/collision/leg_70.stl" scale="1 1 1"/>
      </geometry>
    </collision>
    <visual>
      <origin rpy="0  0  0" xyz="0 0 0"/>
      <geometry>
        <mesh filename="../meshes/stl/visual/leg_70.stl" scale="1 1 1"/>
      </geometry>
    </visual>
  </link>
  <!--===================== Joint description =====================-->
  <joint name="leg_left_0_revolute_joint" type="revolute">
    <child link="leg_left_0"/>
    <parent link="body_1_part"/>
    <origin rpy="0       0.0        0.523598775598" xyz="-0.02825 0.1789304353  0"/>
    <!--=============== Joint properties ===============-->
    <axis xyz="0 -1  0"/>
    <!-- Check -->
    <limit effort="1.5" lower="-1e+5" upper="1e+5" velocity="3.0"/>
  </joint>
  <!--===================== Link description =====================-->
  <link name="leg_right_5">
    <inertial>
      <mass value="0.012706347"/>
      <origin rpy="0 0 0" xyz="-0.013348671 0 -0.027584119"/>
      <inertia ixx="0.000007895" ixy="0" ixz="0.000001300" iyy="0.000009763" iyz="0" izz="0.000002004"/>
    </inertial>
    <collision>
      <origin rpy="0  0  0" xyz="0 0 0"/>
      <geometry>
        <mesh filename="../meshes/stl/collision/leg_70.stl" scale="1 1 1"/>
      </geometry>
    </collision>
    <visual>
      <origin rpy="0  0  0" xyz="0 0 0"/>
      <geometry>
        <mesh filename="../meshes/stl/visual/leg_70.stl" scale="1 1 1"/>
      </geometry>
    </visual>
  </link>
  <!--===================== Joint description =====================-->
  <joint name="leg_right_5_revolute_joint" type="revolute">
    <child link="leg_right_5"/>
    <parent link="body_2_part"/>
    <origin rpy="0       10.471975512        0.523598775598" xyz="0.06325 -0.1789304353  0"/>
    <!--=============== Joint properties ===============-->
    <axis xyz="0 -1  0"/>
    <!-- Check -->
    <limit effort="1.5" lower="-1e+5" upper="1e+5" velocity="3.0"/>
  </joint>
  <!--===================== Link description =====================-->
  <link name="leg_right_4">
    <inertial>
      <mass value="0.012706347"/>
      <origin rpy="0 0 0" xyz="-0.013348671 0 -0.027584119"/>
      <inertia ixx="0.000007895" ixy="0" ixz="0.000001300" iyy="0.000009763" iyz="0" izz="0.000002004"/>
    </inertial>
    <collision>
      <origin rpy="0  0  0" xyz="0 0 0"/>
      <geometry>
        <mesh filename="../meshes/stl/collision/leg_70.stl" scale="1 1 1"/>
      </geometry>
    </collision>
    <visual>
      <origin rpy="0  0  0" xyz="0 0 0"/>
      <geometry>
        <mesh filename="../meshes/stl/visual/leg_70.stl" scale="1 1 1"/>
      </geometry>
    </visual>
  </link>
  <!--===================== Joint description =====================-->
  <joint name="leg_right_4_revolute_joint" type="revolute">
    <child link="leg_right_4"/>
    <parent link="body_2_part"/>
    <origin rpy="0       8.37758040957        0.523598775598" xyz="0.16925 -0.1789304353  0"/>
    <!--=============== Joint properties ===============-->
    <axis xyz="0 -1  0"/>
    <!-- Check -->
    <limit effort="1.5" lower="-1e+5" upper="1e+5" velocity="3.0"/>
  </joint>
  <!--===================== Link description =====================-->
  <link name="leg_right_3">
    <inertial>
      <mass value="0.012706347"/>
      <origin rpy="0 0 0" xyz="-0.013348671 0 -0.027584119"/>
      <inertia ixx="0.000007895" ixy="0" ixz="0.000001300" iyy="0.000009763" iyz="0" izz="0.000002004"/>
    </inertial>
    <collision>
      <origin rpy="0  0  0" xyz="0 0 0"/>
      <geometry>
        <mesh filename="../meshes/stl/collision/leg_70.stl" scale="1 1 1"/>
      </geometry>
    </collision>
    <visual>
      <origin rpy="0  0  0" xyz="0 0 0"/>
      <geometry>
        <mesh filename="../meshes/stl/visual/leg_70.stl" scale="1 1 1"/>
      </geometry>
    </visual>
  </link>
  <!--===================== Joint description =====================-->
  <joint name="leg_right_3_revolute_joint" type="revolute">
    <child link="leg_right_3"/>
    <parent link="body_2_part"/>
    <origin rpy="0       6.28318530718        0.523598775598" xyz="0.27525 -0.1789304353  0"/>
    <!--=============== Joint properties ===============-->
    <axis xyz="0 -1  0"/>
    <!-- Check -->
    <limit effort="1.5" lower="-1e+5" upper="1e+5" velocity="3.0"/>
  </joint>
  <!--===================== Link description =====================-->
  <link name="leg_right_2">
    <inertial>
      <mass value="0.012706347"/>
      <origin rpy="0 0 0" xyz="-0.013348671 0 -0.027584119"/>
      <inertia ixx="0.000007895" ixy="0" ixz="0.000001300" iyy="0.000009763" iyz="0" izz="0.000002004"/>
    </inertial>
    <collision>
      <origin rpy="0  0  0" xyz="0 0 0"/>
      <geometry>
        <mesh filename="../meshes/stl/collision/leg_70.stl" scale="1 1 1"/>
      </geometry>
    </collision>
    <visual>
      <origin rpy="0  0  0" xyz="0 0 0"/>
      <geometry>
        <mesh filename="../meshes/stl/visual/leg_70.stl" scale="1 1 1"/>
      </geometry>
    </visual>
  </link>
  <!--===================== Joint description =====================-->
  <joint name="leg_right_2_revolute_joint" type="revolute">
    <child link="leg_right_2"/>
    <parent link="body_1_part"/>
    <origin rpy="0       4.18879020479        -0.523598775598" xyz="0.18375 -0.1789304353  0"/>
    <!--=============== Joint properties ===============-->
    <axis xyz="0 -1  0"/>
    <!-- Check -->
    <limit effort="1.5" lower="-1e+5" upper="1e+5" velocity="3.0"/>
  </joint>
  <!--===================== Link description =====================-->
  <link name="leg_right_1">
    <inertial>
      <mass value="0.012706347"/>
      <origin rpy="0 0 0" xyz="-0.013348671 0 -0.027584119"/>
      <inertia ixx="0.000007895" ixy="0" ixz="0.000001300" iyy="0.000009763" iyz="0" izz="0.000002004"/>
    </inertial>
    <collision>
      <origin rpy="0  0  0" xyz="0 0 0"/>
      <geometry>
        <mesh filename="../meshes/stl/collision/leg_70.stl" scale="1 1 1"/>
      </geometry>
    </collision>
    <visual>
      <origin rpy="0  0  0" xyz="0 0 0"/>
      <geometry>
        <mesh filename="../meshes/stl/visual/leg_70.stl" scale="1 1 1"/>
      </geometry>
    </visual>
  </link>
  <!--===================== Joint description =====================-->
  <joint name="leg_right_1_revolute_joint" type="revolute">
    <child link="leg_right_1"/>
    <parent link="body_1_part"/>
    <origin rpy="0       2.09439510239        -0.523598775598" xyz="0.07775 -0.1789304353  0"/>
    <!--=============== Joint properties ===============-->
    <axis xyz="0 -1  0"/>
    <!-- Check -->
    <limit effort="1.5" lower="-1e+5" upper="1e+5" velocity="3.0"/>
  </joint>
  <!--===================== Link description =====================-->
  <link name="leg_right_0">
    <inertial>
      <mass value="0.012706347"/>
      <origin rpy="0 0 0" xyz="-0.013348671 0 -0.027584119"/>
      <inertia ixx="0.000007895" ixy="0" ixz="0.000001300" iyy="0.000009763" iyz="0" izz="0.000002004"/>
    </inertial>
    <collision>
      <origin rpy="0  0  0" xyz="0 0 0"/>
      <geometry>
        <mesh filename="../meshes/stl/collision/leg_70.stl" scale="1 1 1"/>
      </geometry>
    </collision>
    <visual>
      <origin rpy="0  0  0" xyz="0 0 0"/>
      <geometry>
        <mesh filename="../meshes/stl/visual/leg_70.stl" scale="1 1 1"/>
      </geometry>
    </visual>
  </link>
  <!--===================== Joint description =====================-->
  <joint name="leg_right_0_revolute_joint" type="revolute">
    <child link="leg_right_0"/>
    <parent link="body_1_part"/>
    <origin rpy="0       0.0        -0.523598775598" xyz="-0.02825 -0.1789304353  0"/>
    <!--=============== Joint properties ===============-->
    <axis xyz="0 -1  0"/>
    <!-- Check -->
    <limit effort="1.5" lower="-1e+5" upper="1e+5" velocity="3.0"/>
  </joint>
</robot>